<?xml version='1.0' encoding='utf-8'?>
<robot name="ur10e_with_hande">
  <link name="world" />
  <ros2_control name="ur10e" type="system">
    <hardware>
      <plugin>ur_robot_driver/URPositionHardwareInterface</plugin>
      <param name="robot_ip">0.0.0.0</param>
      <param name="script_filename" />
      <param name="output_recipe_filename" />
      <param name="input_recipe_filename" />
      <param name="headless_mode">False</param>
      <param name="reverse_port">50001</param>
      <param name="script_sender_port">50002</param>
      <param name="reverse_ip">0.0.0.0</param>
      <param name="script_command_port">50004</param>
      <param name="trajectory_port">50003</param>
      <param name="tf_prefix" />
      <param name="non_blocking_read">True</param>
      <param name="servoj_gain">2000</param>
      <param name="servoj_lookahead_time">0.03</param>
      <param name="use_tool_communication">False</param>
      <param name="kinematics/hash">calib_5119701370761913513</param>
      <param name="tool_voltage">0</param>
      <param name="tool_parity">0</param>
      <param name="tool_baud_rate">115200</param>
      <param name="tool_stop_bits">1</param>
      <param name="tool_rx_idle_chars">1.5</param>
      <param name="tool_tx_idle_chars">3.5</param>
      <param name="tool_device_name">/tmp/ttyUR</param>
      <param name="tool_tcp_port">54321</param>
      <param name="keep_alive_count">2</param>
    </hardware>
    <joint name="shoulder_pan_joint">
      <command_interface name="position" />
      <command_interface name="velocity" />
      <state_interface name="position">
        <param name="initial_value">0.0</param>
      </state_interface>
      <state_interface name="velocity" />
      <state_interface name="effort" />
    </joint>
    <joint name="shoulder_lift_joint">
      <command_interface name="position" />
      <command_interface name="velocity" />
      <state_interface name="position">
        <param name="initial_value">-1.57</param>
      </state_interface>
      <state_interface name="velocity" />
      <state_interface name="effort" />
    </joint>
    <joint name="elbow_joint">
      <command_interface name="position" />
      <command_interface name="velocity" />
      <state_interface name="position">
        <param name="initial_value">0.0</param>
      </state_interface>
      <state_interface name="velocity" />
      <state_interface name="effort" />
    </joint>
    <joint name="wrist_1_joint">
      <command_interface name="position" />
      <command_interface name="velocity" />
      <state_interface name="position">
        <param name="initial_value">-1.57</param>
      </state_interface>
      <state_interface name="velocity" />
      <state_interface name="effort" />
    </joint>
    <joint name="wrist_2_joint">
      <command_interface name="position" />
      <command_interface name="velocity" />
      <state_interface name="position">
        <param name="initial_value">0.0</param>
      </state_interface>
      <state_interface name="velocity" />
      <state_interface name="effort" />
    </joint>
    <joint name="wrist_3_joint">
      <command_interface name="position" />
      <command_interface name="velocity" />
      <state_interface name="position">
        <param name="initial_value">0.0</param>
      </state_interface>
      <state_interface name="velocity" />
      <state_interface name="effort" />
    </joint>
    <sensor name="tcp_fts_sensor">
      <state_interface name="force.x" />
      <state_interface name="force.y" />
      <state_interface name="force.z" />
      <state_interface name="torque.x" />
      <state_interface name="torque.y" />
      <state_interface name="torque.z" />
    </sensor>
    <sensor name="tcp_pose">
      <state_interface name="position.x" />
      <state_interface name="position.y" />
      <state_interface name="position.z" />
      <state_interface name="orientation.x" />
      <state_interface name="orientation.y" />
      <state_interface name="orientation.z" />
      <state_interface name="orientation.w" />
    </sensor>
    <gpio name="speed_scaling">
      <state_interface name="speed_scaling_factor" />
      <param name="initial_speed_scaling_factor">1</param>
      <command_interface name="target_speed_fraction_cmd" />
      <command_interface name="target_speed_fraction_async_success" />
    </gpio>
    <gpio name="gpio">
      <command_interface name="standard_digital_output_cmd_0" />
      <command_interface name="standard_digital_output_cmd_1" />
      <command_interface name="standard_digital_output_cmd_2" />
      <command_interface name="standard_digital_output_cmd_3" />
      <command_interface name="standard_digital_output_cmd_4" />
      <command_interface name="standard_digital_output_cmd_5" />
      <command_interface name="standard_digital_output_cmd_6" />
      <command_interface name="standard_digital_output_cmd_7" />
      <command_interface name="standard_digital_output_cmd_8" />
      <command_interface name="standard_digital_output_cmd_9" />
      <command_interface name="standard_digital_output_cmd_10" />
      <command_interface name="standard_digital_output_cmd_11" />
      <command_interface name="standard_digital_output_cmd_12" />
      <command_interface name="standard_digital_output_cmd_13" />
      <command_interface name="standard_digital_output_cmd_14" />
      <command_interface name="standard_digital_output_cmd_15" />
      <command_interface name="standard_digital_output_cmd_16" />
      <command_interface name="standard_digital_output_cmd_17" />
      <command_interface name="standard_analog_output_cmd_0" />
      <command_interface name="standard_analog_output_cmd_1" />
      <command_interface name="analog_output_domain_cmd" />
      <command_interface name="tool_voltage_cmd" />
      <command_interface name="io_async_success" />
      <state_interface name="digital_output_0" />
      <state_interface name="digital_output_1" />
      <state_interface name="digital_output_2" />
      <state_interface name="digital_output_3" />
      <state_interface name="digital_output_4" />
      <state_interface name="digital_output_5" />
      <state_interface name="digital_output_6" />
      <state_interface name="digital_output_7" />
      <state_interface name="digital_output_8" />
      <state_interface name="digital_output_9" />
      <state_interface name="digital_output_10" />
      <state_interface name="digital_output_11" />
      <state_interface name="digital_output_12" />
      <state_interface name="digital_output_13" />
      <state_interface name="digital_output_14" />
      <state_interface name="digital_output_15" />
      <state_interface name="digital_output_16" />
      <state_interface name="digital_output_17" />
      <state_interface name="digital_input_0" />
      <state_interface name="digital_input_1" />
      <state_interface name="digital_input_2" />
      <state_interface name="digital_input_3" />
      <state_interface name="digital_input_4" />
      <state_interface name="digital_input_5" />
      <state_interface name="digital_input_6" />
      <state_interface name="digital_input_7" />
      <state_interface name="digital_input_8" />
      <state_interface name="digital_input_9" />
      <state_interface name="digital_input_10" />
      <state_interface name="digital_input_11" />
      <state_interface name="digital_input_12" />
      <state_interface name="digital_input_13" />
      <state_interface name="digital_input_14" />
      <state_interface name="digital_input_15" />
      <state_interface name="digital_input_16" />
      <state_interface name="digital_input_17" />
      <state_interface name="standard_analog_output_0" />
      <state_interface name="standard_analog_output_1" />
      <state_interface name="standard_analog_input_0" />
      <state_interface name="standard_analog_input_1" />
      <state_interface name="analog_io_type_0" />
      <state_interface name="analog_io_type_1" />
      <state_interface name="analog_io_type_2" />
      <state_interface name="analog_io_type_3" />
      <state_interface name="tool_mode" />
      <state_interface name="tool_output_voltage" />
      <state_interface name="tool_output_current" />
      <state_interface name="tool_temperature" />
      <state_interface name="tool_analog_input_0" />
      <state_interface name="tool_analog_input_1" />
      <state_interface name="tool_analog_input_type_0" />
      <state_interface name="tool_analog_input_type_1" />
      <state_interface name="robot_mode" />
      <state_interface name="robot_status_bit_0" />
      <state_interface name="robot_status_bit_1" />
      <state_interface name="robot_status_bit_2" />
      <state_interface name="robot_status_bit_3" />
      <state_interface name="safety_mode" />
      <state_interface name="safety_status_bit_0" />
      <state_interface name="safety_status_bit_1" />
      <state_interface name="safety_status_bit_2" />
      <state_interface name="safety_status_bit_3" />
      <state_interface name="safety_status_bit_4" />
      <state_interface name="safety_status_bit_5" />
      <state_interface name="safety_status_bit_6" />
      <state_interface name="safety_status_bit_7" />
      <state_interface name="safety_status_bit_8" />
      <state_interface name="safety_status_bit_9" />
      <state_interface name="safety_status_bit_10" />
      <state_interface name="program_running" />
    </gpio>
    <gpio name="payload">
      <command_interface name="mass" />
      <command_interface name="cog.x" />
      <command_interface name="cog.y" />
      <command_interface name="cog.z" />
      <command_interface name="payload_async_success" />
    </gpio>
    <gpio name="resend_robot_program">
      <command_interface name="resend_robot_program_cmd" />
      <command_interface name="resend_robot_program_async_success" />
    </gpio>
    <gpio name="hand_back_control">
      <command_interface name="hand_back_control_cmd" />
      <command_interface name="hand_back_control_async_success" />
    </gpio>
    <gpio name="zero_ftsensor">
      <command_interface name="zero_ftsensor_cmd" />
      <command_interface name="zero_ftsensor_async_success" />
    </gpio>
    <gpio name="freedrive_mode">
      <command_interface name="async_success" />
      <command_interface name="enable" />
      <command_interface name="abort" />
    </gpio>
    <gpio name="tool_contact">
      <command_interface name="tool_contact_set_state" />
      <state_interface name="tool_contact_result" />
      <state_interface name="tool_contact_state" />
    </gpio>
    <gpio name="system_interface">
      <state_interface name="initialized" />
    </gpio>
    <gpio name="force_mode">
      <command_interface name="task_frame_x" />
      <command_interface name="task_frame_y" />
      <command_interface name="task_frame_z" />
      <command_interface name="task_frame_rx" />
      <command_interface name="task_frame_ry" />
      <command_interface name="task_frame_rz" />
      <command_interface name="selection_vector_x" />
      <command_interface name="selection_vector_y" />
      <command_interface name="selection_vector_z" />
      <command_interface name="selection_vector_rx" />
      <command_interface name="selection_vector_ry" />
      <command_interface name="selection_vector_rz" />
      <command_interface name="wrench_x" />
      <command_interface name="wrench_y" />
      <command_interface name="wrench_z" />
      <command_interface name="wrench_rx" />
      <command_interface name="wrench_ry" />
      <command_interface name="wrench_rz" />
      <command_interface name="limits_x" />
      <command_interface name="limits_y" />
      <command_interface name="limits_z" />
      <command_interface name="limits_rx" />
      <command_interface name="limits_ry" />
      <command_interface name="limits_rz" />
      <command_interface name="type" />
      <command_interface name="damping" />
      <command_interface name="gain_scaling" />
      <command_interface name="disable_cmd" />
      <command_interface name="force_mode_async_success" />
    </gpio>
    <gpio name="trajectory_passthrough">
      <command_interface name="setpoint_positions_0" />
      <command_interface name="setpoint_positions_1" />
      <command_interface name="setpoint_positions_2" />
      <command_interface name="setpoint_positions_3" />
      <command_interface name="setpoint_positions_4" />
      <command_interface name="setpoint_positions_5" />
      <command_interface name="setpoint_velocities_0" />
      <command_interface name="setpoint_velocities_1" />
      <command_interface name="setpoint_velocities_2" />
      <command_interface name="setpoint_velocities_3" />
      <command_interface name="setpoint_velocities_4" />
      <command_interface name="setpoint_velocities_5" />
      <command_interface name="setpoint_accelerations_0" />
      <command_interface name="setpoint_accelerations_1" />
      <command_interface name="setpoint_accelerations_2" />
      <command_interface name="setpoint_accelerations_3" />
      <command_interface name="setpoint_accelerations_4" />
      <command_interface name="setpoint_accelerations_5" />
      <command_interface name="transfer_state" />
      <command_interface name="time_from_start" />
      <command_interface name="abort" />
    </gpio>
    <gpio name="get_robot_software_version">
      <state_interface name="get_version_major" />
      <state_interface name="get_version_minor" />
      <state_interface name="get_version_build" />
      <state_interface name="get_version_bugfix" />
    </gpio>
  </ros2_control>
  <link name="base_link" />
  <link name="base_link_inertia">
    <visual>
      <origin rpy="0 0 3.141592653589793" xyz="0 0 0" />
      <geometry>
        <mesh filename="meshes/ur10e/visual/base.dae" />
      </geometry>
    </visual>
    <collision>
      <origin rpy="0 0 3.141592653589793" xyz="0 0 0" />
      <geometry>
        <mesh filename="meshes/ur10e/collision/base.stl" />
      </geometry>
    </collision>
    <inertial>
      <mass value="4.0" />
      <origin rpy="0 0 0" xyz="0 0 0" />
      <inertia ixx="0.0061063308908" ixy="0.0" ixz="0.0" iyy="0.0061063308908" iyz="0.0" izz="0.01125" />
    </inertial>
  </link>
  <link name="shoulder_link">
    <visual>
      <origin rpy="0 0 3.141592653589793" xyz="0 0 0" />
      <geometry>
        <mesh filename="meshes/ur10e/visual/shoulder.dae" />
      </geometry>
    </visual>
    <collision>
      <origin rpy="0 0 3.141592653589793" xyz="0 0 0" />
      <geometry>
        <mesh filename="meshes/ur10e/collision/shoulder.stl" />
      </geometry>
    </collision>
    <inertial>
      <mass value="7.369" />
      <origin rpy="1.570796326794897 0 0" xyz="0.021 -0.027 0.0" />
      <inertia ixx="0.03408" ixy="2e-05" ixz="-0.00425" iyy="0.03529" iyz="8e-05" izz="0.02156" />
    </inertial>
  </link>
  <link name="upper_arm_link">
    <visual>
      <origin rpy="1.5707963267948966 0 -1.5707963267948966" xyz="0 0 0.1762" />
      <geometry>
        <mesh filename="meshes/ur10e/visual/upperarm.dae" />
      </geometry>
    </visual>
    <collision>
      <origin rpy="1.5707963267948966 0 -1.5707963267948966" xyz="0 0 0.1762" />
      <geometry>
        <mesh filename="meshes/ur10e/collision/upperarm.stl" />
      </geometry>
    </collision>
    <inertial>
      <mass value="13.051" />
      <origin rpy="0 0 0" xyz="-0.2327 0.0 0.158" />
      <inertia ixx="0.02814" ixy="5e-05" ixz="-0.01561" iyy="0.77068" iyz="2e-05" izz="0.76943" />
    </inertial>
  </link>
  <link name="forearm_link">
    <visual>
      <origin rpy="1.5707963267948966 0 -1.5707963267948966" xyz="0 0 0.0393" />
      <geometry>
        <mesh filename="meshes/ur10e/visual/forearm.dae" />
      </geometry>
    </visual>
    <collision>
      <origin rpy="1.5707963267948966 0 -1.5707963267948966" xyz="0 0 0.0393" />
      <geometry>
        <mesh filename="meshes/ur10e/collision/forearm.stl" />
      </geometry>
    </collision>
    <inertial>
      <mass value="3.989" />
      <origin rpy="0 0 0" xyz="-0.33155 0.0 0.068" />
      <inertia ixx="0.01014" ixy="8e-05" ixz="0.00916" iyy="0.30928" iyz="0.0" izz="0.30646" />
    </inertial>
  </link>
  <link name="wrist_1_link">
    <visual>
      <origin rpy="1.5707963267948966 0 0" xyz="0 0 -0.135" />
      <geometry>
        <mesh filename="meshes/ur10e/visual/wrist1.dae" />
      </geometry>
    </visual>
    <collision>
      <origin rpy="1.5707963267948966 0 0" xyz="0 0 -0.135" />
      <geometry>
        <mesh filename="meshes/ur10e/collision/wrist1.stl" />
      </geometry>
    </collision>
    <inertial>
      <mass value="2.1" />
      <origin rpy="1.570796326794897 0 0" xyz="0.0 -0.018 0.007" />
      <inertia ixx="0.00296" ixy="-1e-05" ixz="0.0" iyy="0.00222" iyz="-0.00024" izz="0.00258" />
    </inertial>
  </link>
  <link name="wrist_2_link">
    <visual>
      <origin rpy="0 0 0" xyz="0 0 -0.12" />
      <geometry>
        <mesh filename="meshes/ur10e/visual/wrist2.dae" />
      </geometry>
    </visual>
    <collision>
      <origin rpy="0 0 0" xyz="0 0 -0.12" />
      <geometry>
        <mesh filename="meshes/ur10e/collision/wrist2.stl" />
      </geometry>
    </collision>
    <inertial>
      <mass value="1.98" />
      <origin rpy="-1.570796326794897 0 0" xyz="0.0 0.018 -0.007" />
      <inertia ixx="0.00296" ixy="-1e-05" ixz="0.0" iyy="0.00222" iyz="-0.00024" izz="0.00258" />
    </inertial>
  </link>
  <link name="wrist_3_link">
    <visual>
      <origin rpy="1.5707963267948966 0 0" xyz="0 0 -0.1168" />
      <geometry>
        <mesh filename="meshes/ur10e/visual/wrist3.dae" />
      </geometry>
    </visual>
    <collision>
      <origin rpy="1.5707963267948966 0 0" xyz="0 0 -0.1168" />
      <geometry>
        <mesh filename="meshes/ur10e/collision/wrist3.stl" />
      </geometry>
    </collision>
    <inertial>
      <mass value="0.615" />
      <origin rpy="0 0 0" xyz="0.0 0.0 -0.026" />
      <inertia ixx="0.0004" ixy="0.0" ixz="0.0" iyy="0.00041" iyz="0.0" izz="0.00034" />
    </inertial>
  </link>
  <joint name="base_joint" type="fixed">
    <origin rpy="0 0 0" xyz="0 0 0" />
    <parent link="world" />
    <child link="base_link" />
  </joint>
  <joint name="base_link-base_link_inertia" type="fixed">
    <parent link="base_link" />
    <child link="base_link_inertia" />
    <origin rpy="0 0 3.141592653589793" xyz="0 0 0" />
  </joint>
  <joint name="shoulder_pan_joint" type="revolute">
    <parent link="base_link_inertia" />
    <child link="shoulder_link" />
    <origin rpy="0 0 0" xyz="0 0 0.1807" />
    <axis xyz="0 0 1" />
    <limit effort="330.0" lower="-6.283185307179586" upper="6.283185307179586" velocity="2.0943951023931953" />
    <dynamics damping="0" friction="0" />
  </joint>
  <joint name="shoulder_lift_joint" type="revolute">
    <parent link="shoulder_link" />
    <child link="upper_arm_link" />
    <origin rpy="1.570796327 0 0" xyz="0 0 0" />
    <axis xyz="0 0 1" />
    <limit effort="330.0" lower="-6.283185307179586" upper="6.283185307179586" velocity="2.0943951023931953" />
    <dynamics damping="0" friction="0" />
  </joint>
  <joint name="elbow_joint" type="revolute">
    <parent link="upper_arm_link" />
    <child link="forearm_link" />
    <origin rpy="0 0 0" xyz="-0.6127 0 0" />
    <axis xyz="0 0 1" />
    <limit effort="150.0" lower="-3.141592653589793" upper="3.141592653589793" velocity="3.141592653589793" />
    <dynamics damping="0" friction="0" />
  </joint>
  <joint name="wrist_1_joint" type="revolute">
    <parent link="forearm_link" />
    <child link="wrist_1_link" />
    <origin rpy="0 0 0" xyz="-0.57155 0 0.17415" />
    <axis xyz="0 0 1" />
    <limit effort="54.0" lower="-6.283185307179586" upper="6.283185307179586" velocity="3.141592653589793" />
    <dynamics damping="0" friction="0" />
  </joint>
  <joint name="wrist_2_joint" type="revolute">
    <parent link="wrist_1_link" />
    <child link="wrist_2_link" />
    <origin rpy="1.570796327 0 0" xyz="0 -0.11985 -2.458164590756244e-11" />
    <axis xyz="0 0 1" />
    <limit effort="54.0" lower="-6.283185307179586" upper="6.283185307179586" velocity="3.141592653589793" />
    <dynamics damping="0" friction="0" />
  </joint>
  <joint name="wrist_3_joint" type="revolute">
    <parent link="wrist_2_link" />
    <child link="wrist_3_link" />
    <origin rpy="1.570796326589793 3.141592653589793 3.141592653589793" xyz="0 0.11655 -2.390480459346185e-11" />
    <axis xyz="0 0 1" />
    <limit effort="54.0" lower="-6.283185307179586" upper="6.283185307179586" velocity="3.141592653589793" />
    <dynamics damping="0" friction="0" />
  </joint>
  <link name="ft_frame" />
  <joint name="wrist_3_link-ft_frame" type="fixed">
    <parent link="wrist_3_link" />
    <child link="ft_frame" />
    <origin rpy="3.141592653589793 0 0" xyz="0 0 0" />
  </joint>
  <link name="base" />
  <joint name="base_link-base_fixed_joint" type="fixed">
    <origin rpy="0 0 3.141592653589793" xyz="0 0 0" />
    <parent link="base_link" />
    <child link="base" />
  </joint>
  <link name="flange" />
  <joint name="wrist_3-flange" type="fixed">
    <parent link="wrist_3_link" />
    <child link="flange" />
    <origin rpy="0 -1.5707963267948966 -1.5707963267948966" xyz="0 0 0" />
  </joint>
  <link name="tool0" />
  <joint name="flange-tool0" type="fixed">
    <origin rpy="1.5707963267948966 0 1.5707963267948966" xyz="0 0 0" />
    <parent link="flange" />
    <child link="tool0" />
  </joint>
  <link name="robotiq_hande_coupler">
    <visual>
      <geometry>
        <mesh filename="meshes/hande/io_coupler.dae" />
      </geometry>
    </visual>
    <collision>
      <origin rpy="0 0 0" xyz="0 0 0.005449999999999999" />
      <geometry>
        <cylinder length="0.0169" radius="0.0385" />
      </geometry>
    </collision>
    <inertial>
      <mass value="0.119" />
      <origin rpy="0 0 0" xyz="0 0 0.005449999999999999" />
      <inertia ixx="4.4668218799372e-05" ixy="0.0" ixz="0.0" iyy="4.4668218799372e-05" iyz="0.0" izz="8.367187499999999e-05" />
    </inertial>
  </link>
  <link name="robotiq_hande_link">
    <visual>
      <origin rpy="0 0 0" xyz="0 0 0" />
      <geometry>
        <mesh filename="meshes/hande/hande.dae" scale="1.0 1.0 1.0" />
      </geometry>
    </visual>
    <collision>
      <origin rpy="0 0 0" xyz="0 0 0.053450000000000004" />
      <geometry>
        <cylinder length="0.10690000000000001" radius="0.0385" />
      </geometry>
    </collision>
    <inertial>
      <mass value="0.86387" />
      <origin rpy="0 0 0" xyz="0 0 0.0495" />
      <inertia ixx="0.0010092697156669523" ixy="0.0" ixz="0.0" iyy="0.0010092697156669523" iyz="0.0" izz="0.00060740859375" />
    </inertial>
  </link>
  <link name="robotiq_hande_left_finger">
    <visual>
      <origin rpy="0 0 0" xyz="0 0 0" />
      <geometry>
        <mesh filename="meshes/hande/finger.dae" scale="1.0 1.0 1.0" />
      </geometry>
    </visual>
    <collision>
      <origin rpy="0 0 0" xyz="0 0 0" />
      <geometry>
        <mesh filename="meshes/hande/finger_collision.dae" scale="1.0 1.0 1.0" />
      </geometry>
    </collision>
    <inertial>
      <origin rpy="0 0 0" xyz="0 0 0" />
      <mass value="0.03804" />
      <inertia ixx="1E-9" ixy="0.0" ixz="0.0" iyy="1E-9" iyz="0.0" izz="1E-9" />
    </inertial>
  </link>
  <link name="robotiq_hande_right_finger">
    <visual>
      <origin rpy="0 0 3.141592653589793" xyz="0 0 0" />
      <geometry>
        <mesh filename="meshes/hande/finger.dae" scale="1.0 1.0 1.0" />
      </geometry>
    </visual>
    <collision>
      <origin rpy="0 0 3.141592653589793" xyz="0 0 0" />
      <geometry>
        <mesh filename="meshes/hande/finger_collision.dae" scale="1.0 1.0 1.0" />
      </geometry>
    </collision>
    <inertial>
      <origin rpy="0 0 0" xyz="0 0 0" />
      <mass value="0.03804" />
      <inertia ixx="1E-9" ixy="0.0" ixz="0.0" iyy="1E-9" iyz="0.0" izz="1E-9" />
    </inertial>
  </link>
  <link name="robotiq_hande_end" />
  <joint name="robotiq_hande_base_joint" type="fixed">
    <origin rpy="0 0 0" xyz="0 0 0.011" />
    <parent link="robotiq_hande_coupler" />
    <child link="robotiq_hande_link" />
  </joint>
  <joint name="robotiq_hande_left_finger_joint" type="prismatic">
    <origin rpy="0 0 0" xyz="0 0 0.099" />
    <parent link="robotiq_hande_link" />
    <child link="robotiq_hande_left_finger" />
    <axis xyz="1 0 0" />
    <limit effort="130" lower="0" upper="0.025" velocity="0.15" />
  </joint>
  <joint name="robotiq_hande_right_finger_joint" type="prismatic">
    <origin rpy="0 0 0" xyz="0 0 0.099" />
    <parent link="robotiq_hande_link" />
    <child link="robotiq_hande_right_finger" />
    <axis xyz="-1 0 0" />
    <limit effort="130" lower="0" upper="0.025" velocity="0.15" />
    <mimic joint="robotiq_hande_left_finger_joint" multiplier="1" offset="0" />
  </joint>
  <joint name="robotiq_hande_end_joint" type="fixed">
    <origin rpy="0 0 0" xyz="0 0 0.14550000000000002" />
    <parent link="robotiq_hande_link" />
    <child link="robotiq_hande_end" />
  </joint>
  <joint name="tool0_to_hande_gripper" type="fixed">
    <parent link="tool0" />
    <child link="robotiq_hande_coupler" />
    <origin xyz="0 0 0" rpy="0 0 0" />
  </joint>
</robot>